Workbook
Name nem_modosithato2: SuccessCriteria!$J$1

Sheet Cover
B1: Web-development course (Homepage Success Criteria list) | J1: Version: v2024252_v2
B2: Your name:
B3: Your Neptun code:
B4: Your email address:
B5: For testing purposes, it is worth publishing the website on a web server before submission. However, the compressed package uploaded to Canvas, which we publish on our own web server, will be evaluated.
B6: List of Success Criteria
B7: There are highlighted principles (marked with a yellow background and bold highlighting) among the guidelines, which must be observed with special attention! To obtain a satisfactory grade, at least 50 points must be achieved. Regarding student and tutor evaluation, there can be a maximum of 15 deviations from the guidelines, in case of more than this, we cannot accept the assignment.
B9: Guidelines
B10: Number of success criteria | D10: =COUNTA(SuccessCriteria!B:B)-1 -> 47 | F10: Please fill out the table in Excel (installed in labs), as the processing application only works on the original XLSX files. We will not accept tables in other formats.
B11: Available maximum points | D11: =SUM(SuccessCriteria!I:I) -> 100
B12: Minimum points to be achieved | D12: 50
B13: Points given for the self-evaluation
B14: You have fulfilled every mandatory success criteria | D14: =IF(COUNTIFS(SuccessCriteria!D2:D48,"=1",SuccessCriteria!H2:H48,"=igaz")=19,TRUE,FALSE) -> FALSE
B15: Achieved points according the self check | D15: =SUM(SuccessCriteria!J2:J48) -> 79 | F15: =CONCATENATE("If we were to evaluate the assignment independently, you would receive a ",VLOOKUP(D15,Ponthatárok!$C$3:$D$7,2,TRUE), " grade based on your self-evaluation.") -> If we were to evaluate the assignment independently, you would receive a good grade based on your self-evaluation.
B16: Points given by the tutor
B17: You have fulfilled every mandatory success criteria | D17: =IF(D26=TRUE,IF(COUNTIFS(SuccessCriteria!F2:F48,"=1",SuccessCriteria!H2:H48,"=igaz")=19,TRUE,FALSE),"No data yet.") -> FALSE | F17: It only matters if the tutor has already completed the evaluation.
B18: Achieved points according to tutor's review | D18: =IF(D26=TRUE,SUM(SuccessCriteria!K2:K48),"No data yet.") -> 75
B19: Achieved points including extra points or point reduction | D19: =IF(D26=TRUE,D18+D27,"No data yet.") -> 65
B20: Points given by the tutor for the self-check correctness
B21: Available maximum points | D21: 20 | F21: It only matters if the tutor has already completed the evaluation.
B22: Minimum points to be achieved | D22: 10
B23: Difference between self and tutor evaluation | D23: =IF(D26=TRUE,SUM(SuccessCriteria!L2:L48),"No data yet.") -> 5
B24: Achieved points | D24: =IF(D26,IF(ROUNDUP(20 - 0.71*D23,0)>0,ROUNDUP(20 - 0.71*D23,0),0),"No data yet.") -> 17
B26: The tutor has finished the review process | D26: TRUE
B27: Extra points or point reduction | D27: -10
B28: Remarks of the tutor (optional)
B29: Not using only CSS, HTML and Bootstrap.

Sheet SuccessCriteria
B1: Category | C1: Success Criteria | D1: 1=True / 0 = false (self check) | E1: Remark of student | F1: 1=True / 0 = false (tutor's review) | G1: Remark of tutor | H1: Mandatory Success Criteria | I1: Points, if succeed | J1: Achieved points (self check) | K1: Achieved points (tutor's review) | L1: Difference | M1: Critics
A2: 1 | B2: Course requirement | C2: The website consists of at least three static HTML pages, the home page is saved as index.html. All HTML pages in the package are linked to the pages, there is no unnecessary HTML file. The pages are linked relatively, there is no reference to the root folder. | D2: 1 | F2: 1 | H2: TRUE | I2: 3 | J2: =IF(D2=1,I2,IF(H2="TRUE",-5,"")) -> 3 | K2: =IF(F2=1,I2,IF(H2=TRUE,-5,"")) -> 3 | L2: =IF(J2=K2,0,1) -> 0
A3: =A2+1 -> 2 | B3: Course requirement | C3: There is (at least one) page that contains a background image (The background image does not have to be the background of the page, it can be any component.) | D3: 1 | F3: 1 | H3: TRUE | I3: 2 | J3: =IF(D3=1,I3,IF(H3="TRUE",-5,"")) -> 2 | K3: =IF(F3=1,I3,IF(H3=TRUE,-5,"")) -> 2 | L3: =IF(J3=K3,0,1) -> 0
A4: =A3+1 -> 3 | B4: Course requirement | C4: At least 5 images are inserted on the pages (in total), at least two images function as thumbnails, i.e. they link to a larger version of the image | D4: 1 | F4: 1 | H4: TRUE | I4: 3 | J4: =IF(D4=1,I4,IF(H4="TRUE",-5,"")) -> 3 | K4: =IF(F4=1,I4,IF(H4=TRUE,-5,"")) -> 3 | L4: =IF(J4=K4,0,1) -> 0
A5: =A4+1 -> 4 | B5: Course requirement | C5: There is a page that has a data table that is at least 2x3, has header cells (<th>) and a caption (<caption>) that has been created as expandable content using the <summary> tag embedded in the <details> tag. The structure of the page should not be implemented using a table! | D5: 1 | F5: 0 | G5: Missing summary, details and caption. | H5: TRUE | I5: 3 | J5: =IF(D5=1,I5,IF(H5="TRUE",-5,"")) -> 3 | K5: =IF(F5=1,I5,IF(H5=TRUE,-5,"")) | L5: =IF(J5=K5,0,1) -> 1
A6: =A5+1 -> 5 | B6: Course requirement | C6: There is a page that contains a form that contains at least one text field, one text area, at least 2 radio buttons, at least 1 checkbox, and a submit button. | D6: 1 | E6: Explore.html | F6: 1 | H6: TRUE | I6: 3 | J6: =IF(D6=1,I6,IF(H6="TRUE",-5,"")) -> 3 | K6: =IF(F6=1,I6,IF(H6=TRUE,-5,"")) -> 3 | L6: =IF(J6=K6,0,1) -> 0
A7: =A6+1 -> 6 | B7: Course requirement | C7: There is a page that has JavaScript code that improves the user experience (e.g. selection from an alternative style sheet, font size change, image gallery, ...) Components of the Bootstrap framework are also acceptable at this point (e.g. Carousel). | D7: 1 | E7: explore.html, index.html | F7: 1 | H7: TRUE | I7: 3 | J7: =IF(D7=1,I7,IF(H7="TRUE",-5,"")) -> 3 | K7: =IF(F7=1,I7,IF(H7=TRUE,-5,"")) -> 3 | L7: =IF(J7=K7,0,1) -> 0
A8: =A7+1 -> 7 | B8: Course requirement | C8: All pages are filled with content, in addition to structural links, they also contain at least 3 external links (in total). Pages filled with Lorem ipsum, etc. filler texts are not acceptable! Structural links are given relative to the current page... | D8: 1 | F8: 1 | H8: TRUE | I8: 2 | J8: =IF(D8=1,I8,IF(H8="TRUE",-5,"")) -> 2 | K8: =IF(F8=1,I8,IF(H8=TRUE,-5,"")) -> 2 | L8: =IF(J8=K8,0,1) -> 0
A9: =A8+1 -> 8 | B9: Course requirement | C9: There are examples of each of the following tags being used on the HTML5 page(s): <header><nav><section><article><aside><footer><figure><video>. Tags do not have to appear on every page, but when their use is semantically justified, the appropriate tag MUST be used! | D9: 1 | F9: 0 | G9: Missing aside. | H9: TRUE | I9: 4 | J9: =IF(D9=1,I9,IF(H9="TRUE",-5,"")) -> 4 | K9: =IF(F9=1,I9,IF(H9=TRUE,-5,"")) | L9: =IF(J9=K9,0,1) -> 1
A10: =A9+1 -> 9 | B10: Page layout and visual design | C10: The website is responsive. In addition, it is true that for at least 1 page, at least three layouts are implemented depending on the display size (smartphone, tablet, larger display), of which the layout designed for the (smallest) display size consists of a single column, and the layout designed for the (largest) display size consists of at least two columns. Content elements (including images and videos) are sized relatively on each page. | D10: 1 | F10: 1 | H10: TRUE | I10: 5 | J10: =IF(D10=1,I10,IF(H10="TRUE",-5,"")) -> 5 | K10: =IF(F10=1,I10,IF(H10=TRUE,-5,"")) -> 5 | L10: =IF(J10=K10,0,1) -> 0
A11: =A10+1 -> 10 | B11: Page layout and visual design | C11: Content and appearance (design) are separated appropriately with the use of external style sheets. Inline specification should be avoided unless there is a specific reason for its use! | D11: 1 | F11: 1 | H11: TRUE | I11: 3 | J11: =IF(D11=1,I11,IF(H11="TRUE",-5,"")) -> 3 | K11: =IF(F11=1,I11,IF(H11=TRUE,-5,"")) -> 3 | L11: =IF(J11=K11,0,1) -> 0
A12: =A11+1 -> 11 | B12: Page layout and visual design | C12: The pages have unique titles, and start with a keyword (eg. About me – Website of Thomas Smith) Each page is clearly labelled with a descriptive and useful title that makes sense as a bookmark | D12: 1 | F12: 1 | I12: 1 | J12: =IF(D12=1,I12,IF(H12="TRUE",-5,"")) -> 1 | K12: =IF(F12=1,I12,IF(H12=TRUE,-5,"")) -> 1 | L12: =IF(J12=K12,0,1) -> 0
A13: =A12+1 -> 12 | B13: Page layout and visual design | C13: The text is readable with the default font size | D13: 1 | F13: 1 | I13: 1 | J13: =IF(D13=1,I13,IF(H13="TRUE",-5,"")) -> 1 | K13: =IF(F13=1,I13,IF(H13=TRUE,-5,"")) -> 1 | L13: =IF(J13=K13,0,1) -> 0
A14: =A13+1 -> 13 | B14: Page layout and visual design | C14: At the font settings, besides concrete font types, general font families are also given; for smaller text sans-serif font type is set | D14: 1 | F14: 1 | I14: 1 | J14: =IF(D14=1,I14,IF(H14="TRUE",-5,"")) -> 1 | K14: =IF(F14=1,I14,IF(H14=TRUE,-5,"")) -> 1 | L14: =IF(J14=K14,0,1) -> 0
A15: =A14+1 -> 14 | B15: Page layout and visual design | C15: Font size is set in a way that text could be easily resized (% or em or rem) | D15: 1 | F15: 0 | G15: Pixels in the css. | I15: 1 | J15: =IF(D15=1,I15,IF(H15="TRUE",-5,"")) -> 1 | K15: =IF(F15=1,I15,IF(H15=TRUE,-5,"")) | L15: =IF(J15=K15,0,1) -> 1
A16: =A15+1 -> 15 | B16: Page layout and visual design | C16: The navigation menu is at the top or on the left side of the page, it can be clearly distinguished from the main content | D16: 1 | F16: 1 | I16: 1 | J16: =IF(D16=1,I16,IF(H16="TRUE",-5,"")) -> 1 | K16: =IF(F16=1,I16,IF(H16=TRUE,-5,"")) -> 1 | L16: =IF(J16=K16,0,1) -> 0
A17: =A16+1 -> 16 | B17: Page layout and visual design | C17: Visited and non-visited links are different in appearance, the contrast of visited links is higher that that of non-visited links | D17: 1 | F17: 1 | I17: 1 | J17: =IF(D17=1,I17,IF(H17="TRUE",-5,"")) -> 1 | K17: =IF(F17=1,I17,IF(H17=TRUE,-5,"")) -> 1 | L17: =IF(J17=K17,0,1) -> 0
A18: =A17+1 -> 17 | B18: Page layout and visual design | C18: There should be no underlined texts that are not links | D18: 1 | F18: 1 | I18: 1 | J18: =IF(D18=1,I18,IF(H18="TRUE",-5,"")) -> 1 | K18: =IF(F18=1,I18,IF(H18=TRUE,-5,"")) -> 1 | L18: =IF(J18=K18,0,1) -> 0
A19: =A18+1 -> 18 | B19: Page layout and visual design | C19: Links should be underlined (navigation menu and list of links might be an exemption) It's not enough that the underline only appears when the user hovers over the link. The underline must always be visible. | D19: 1 | F19: 1 | I19: 1 | J19: =IF(D19=1,I19,IF(H19="TRUE",-5,"")) -> 1 | K19: =IF(F19=1,I19,IF(H19=TRUE,-5,"")) -> 1 | L19: =IF(J19=K19,0,1) -> 0
A20: =A19+1 -> 19 | B20: Page layout and visual design | C20: Pages should be printable, the print preview should show all the important information Separate style sheets should be created for the screen and the printer. In the print view, elements that are repeated on every page, such as the menu, header, sidebar, etc., should be removed. Videos should be hidden and images should be scaled down. Text should fill the pages in a way that saves paper and ink. | D20: 1 | F20: 1 | I20: 3 | J20: =IF(D20=1,I20,IF(H20="TRUE",-5,"")) -> 3 | K20: =IF(F20=1,I20,IF(H20=TRUE,-5,"")) -> 3 | L20: =IF(J20=K20,0,1) -> 0
A21: =A20+1 -> 20 | B21: Page layout and visual design | C21: Fields on forms have labels, which clearly explain what entries are desired. (<label for="">) | D21: 1 | F21: 1 | I21: 3 | J21: =IF(D21=1,I21,IF(H21="TRUE",-5,"")) -> 3 | K21: =IF(F21=1,I21,IF(H21=TRUE,-5,"")) -> 3 | L21: =IF(J21=K21,0,1) -> 0
A22: =A21+1 -> 21 | B22: Page layout and visual design | C22: The length of text boxes on forms is set according to the expected answer The size of the text fields and the maximum length of the text that can be entered must also be set. A style sheet can also be used to set the size. | D22: 1 | F22: 1 | I22: 1 | J22: =IF(D22=1,I22,IF(H22="TRUE",-5,"")) -> 1 | K22: =IF(F22=1,I22,IF(H22=TRUE,-5,"")) -> 1 | L22: =IF(J22=K22,0,1) -> 0
A23: =A22+1 -> 22 | B23: Page layout and visual design | C23: Labels are close to the data entry fields | D23: 1 | F23: 1 | I23: 1 | J23: =IF(D23=1,I23,IF(H23="TRUE",-5,"")) -> 1 | K23: =IF(F23=1,I23,IF(H23=TRUE,-5,"")) -> 1 | L23: =IF(J23=K23,0,1) -> 0
A24: =A23+1 -> 23 | B24: Page layout and visual design | C24: The form content can be sent (emailed via post method or processed in another way) | D24: 1 | F24: 0 | G24: Form action is not valid (must be a valid email address for mailto: links) | I24: 1 | J24: =IF(D24=1,I24,IF(H24="TRUE",-5,"")) -> 1 | K24: =IF(F24=1,I24,IF(H24=TRUE,-5,"")) | L24: =IF(J24=K24,0,1) -> 1
A25: =A24+1 -> 24 | B25: Page layout and visual design | C25: Radio buttons cover all the possible answers (options should be carefully designed) | D25: 1 | F25: 1 | I25: 1 | J25: =IF(D25=1,I25,IF(H25="TRUE",-5,"")) -> 1 | K25: =IF(F25=1,I25,IF(H25=TRUE,-5,"")) -> 1 | L25: =IF(J25=K25,0,1) -> 0
A26: =A25+1 -> 25 | B26: Page layout and visual design | C26: The function of buttons in a form is clearly indicated by their label | D26: 1 | F26: 1 | I26: 1 | J26: =IF(D26=1,I26,IF(H26="TRUE",-5,"")) -> 1 | K26: =IF(F26=1,I26,IF(H26=TRUE,-5,"")) -> 1 | L26: =IF(J26=K26,0,1) -> 0
A27: =A26+1 -> 26 | B27: Content design | C27: Based on the scanning principle, keywords are emphasized, and if it is necessary, lists are used | D27: 1 | F27: 1 | I27: 2 | J27: =IF(D27=1,I27,IF(H27="TRUE",-5,"")) -> 2 | K27: =IF(F27=1,I27,IF(H27=TRUE,-5,"")) -> 2 | L27: =IF(J27=K27,0,1) -> 0
A28: =A27+1 -> 27 | B28: Content design | C28: Well formulated headings (<h1>…<h6>) structure the text on each page On HTML5 pages, heading levels can also be set using <h1> headings within nested page structure elements. If subheadings are not necessary, a single <h1> tag is sufficient. | D28: 1 | F28: 1 | I28: 2 | J28: =IF(D28=1,I28,IF(H28="TRUE",-5,"")) -> 2 | K28: =IF(F28=1,I28,IF(H28=TRUE,-5,"")) -> 2 | L28: =IF(J28=K28,0,1) -> 0
A29: =A28+1 -> 28 | B29: Content design | C29: It is true for all pages that the headings are logically nested within each other, for example, there cannot be a heading that only plays the role of heading 2 on the page, heading 1 cannot have a subheading that plays the role of subheading 3, and so on. The point can only be given if at least one heading that plays the role of heading 2 occurs on one of the pages (which on an HTML5 page can also be a heading 1 that is included in an embedded page structure element) | D29: 1 | F29: 1 | I29: 2 | J29: =IF(D29=1,I29,IF(H29="TRUE",-5,"")) -> 2 | K29: =IF(F29=1,I29,IF(H29=TRUE,-5,"")) -> 2 | L29: =IF(J29=K29,0,1) -> 0
A30: =A29+1 -> 29 | B30: Content design | C30: The background shouldn't have a pattern that makes reading the text difficult | D30: 1 | F30: 1 | I30: 1 | J30: =IF(D30=1,I30,IF(H30="TRUE",-5,"")) -> 1 | K30: =IF(F30=1,I30,IF(H30=TRUE,-5,"")) -> 1 | L30: =IF(J30=K30,0,1) -> 0
A31: =A30+1 -> 30 | B31: Content design | C31: Text blocks and lists are left aligned (or justified) | D31: 1 | F31: 1 | I31: 1 | J31: =IF(D31=1,I31,IF(H31="TRUE",-5,"")) -> 1 | K31: =IF(F31=1,I31,IF(H31=TRUE,-5,"")) -> 1 | L31: =IF(J31=K31,0,1) -> 0
A32: =A31+1 -> 31 | B32: Content design | C32: A frame (poster) is cut and shown from the video, so that the user could decide whether it is worth watching the video. | F32: 0 | I32: 3 | J32: =IF(D32=1,I32,IF(H32="TRUE",-5,"")) | K32: =IF(F32=1,I32,IF(H32=TRUE,-5,"")) | L32: =IF(J32=K32,0,1) -> 0
A33: =A32+1 -> 32 | B33: Content design | C33: The same structural links are present on every page, in the same order | D33: 1 | F33: 1 | I33: 1 | J33: =IF(D33=1,I33,IF(H33="TRUE",-5,"")) -> 1 | K33: =IF(F33=1,I33,IF(H33=TRUE,-5,"")) -> 1 | L33: =IF(J33=K33,0,1) -> 0
A34: =A33+1 -> 33 | B34: Content design | C34: You can return to the home page from any page using a link (e.g., the home page menu item or icon in the menu). | D34: 1 | F34: 1 | G34: Homepage is accessible from every page. | I34: 1 | J34: =IF(D34=1,I34,IF(H34="TRUE",-5,"")) -> 1 | K34: =IF(F34=1,I34,IF(H34=TRUE,-5,"")) -> 1 | L34: =IF(J34=K34,0,1) -> 0
A35: =A34+1 -> 34 | B35: Content design | C35: If someone arrives at a page on the website from an external site, it is clear to them which page they are on (e.g. distinguishing the current page in the menu, breadcrumb navigation, etc.) It is not enough to repeat the name of the menu item (for example) as a headline. | D35: 1 | F35: 1 | G35: Current page is clearly indicated on every page. | I35: 2 | J35: =IF(D35=1,I35,IF(H35="TRUE",-5,"")) -> 2 | K35: =IF(F35=1,I35,IF(H35=TRUE,-5,"")) -> 2 | L35: =IF(J35=K35,0,1) -> 0
A36: =A35+1 -> 35 | B36: Accessibility | C36: For pictures not displayed with a design purpose, the ALT attribute is precisely filled in. (WCAG 2.0 1.1.1) | D36: 1 | F36: 1 | G36: ALT attribute is properly filled out for each image. | H36: TRUE | I36: 4 | J36: =IF(D36=1,I36,IF(H36="TRUE",-5,"")) -> 4 | K36: =IF(F36=1,I36,IF(H36=TRUE,-5,"")) -> 4 | L36: =IF(J36=K36,0,1) -> 0
A37: =A36+1 -> 36 | B37: Accessibility | C37: The link texts themselves are self-explanatory (the text "click here" is not appropriate), concise | D37: 1 | F37: 1 | I37: 1 | J37: =IF(D37=1,I37,IF(H37="TRUE",-5,"")) -> 1 | K37: =IF(F37=1,I37,IF(H37=TRUE,-5,"")) -> 1 | L37: =IF(J37=K37,0,1) -> 0
A38: =A37+1 -> 37 | B38: Accessibility | C38: Texts are easily readable, contrast ratio is well-chosen (WCAG 2.0 1.4.3) | D38: 1 | F38: 1 | G38: Appropriate contrast ratio is ensured for all text. | H38: TRUE | I38: 2 | J38: =IF(D38=1,I38,IF(H38="TRUE",-5,"")) -> 2 | K38: =IF(F38=1,I38,IF(H38=TRUE,-5,"")) -> 2 | L38: =IF(J38=K38,0,1) -> 0
A39: =A38+1 -> 38 | B39: Accessibility | C39: An alternative, large-font, high-contrast style version is available for visually impaired users on all pages. | F39: 0 | I39: 5 | J39: =IF(D39=1,I39,IF(H39="TRUE",-5,"")) | K39: =IF(F39=1,I39,IF(H39=TRUE,-5,"")) | L39: =IF(J39=K39,0,1) -> 0
A40: =A39+1 -> 39 | B40: Accessibility | C40: A mechanism is available to bypass blocks of content that are repeated on multiple Web pages. (WCAG 2.0 2.4.1) The link used to jump to content should be accessible to screen reader users and should not appear in visual browsers. | F40: 0 | H40: TRUE | I40: 3 | J40: =IF(D40=1,I40,IF(H40="TRUE",-5,"")) -> -5 | K40: =IF(F40=1,I40,IF(H40=TRUE,-5,"")) | L40: =IF(J40=K40,0,1) -> 1
...

Sheet Statistics (self check)
B1: Statistics (self-check)
C2: succeded | D2: not succeded | E2: sum | F2: ratio
B3: Course requirement | C3: =COUNTIFS(SuccessCriteria!B2:B48,"="&B3,SuccessCriteria!D2:D48,1) -> 8 | D3: =E3-C3 -> 0 | E3: 8 | F3: =C3/E3 -> 1
B4: Page layout and visual design | C4: =COUNTIFS(SuccessCriteria!B3:B49,"="&B4,SuccessCriteria!D3:D49,1) -> 17 | D4: =E4-C4 -> 0 | E4: 17 | F4: =C4/E4 -> 1
B5: Content design | C5: =COUNTIFS(SuccessCriteria!B4:B50,"="&B5,SuccessCriteria!D4:D50,1) -> 8 | D5: =E5-C5 -> 1 | E5: 9 | F5: =C5/E5 -> 0.88888889
B6: Accessibility | C6: =COUNTIFS(SuccessCriteria!B5:B51,"="&B6,SuccessCriteria!D5:D51,1) -> 4 | D6: =E6-C6 -> 3 | E6: 7 | F6: =C6/E6 -> 0.57142857
B7: Testing | C7: =COUNTIFS(SuccessCriteria!B6:B52,"="&B7,SuccessCriteria!D6:D52,1) -> 6 | D7: =E7-C7 -> 0 | E7: 6 | F7: =C7/E7 -> 1
B8: Summary | C8: =SUM(C3:C7) -> 43 | D8: =SUM(D3:D7) -> 4 | E8: =SUM(E3:E7) -> 47 | F8: =C8/E8 -> 0.91489362

Sheet Statistics (tutor)
B1: Statistics (tutor's review)
C2: succeded | D2: not succeded | E2: sum | F2: ratio
B3: Course requirement | C3: =COUNTIFS(SuccessCriteria!B2:B48,"="&B3,SuccessCriteria!F2:F48,1) -> 6 | D3: =E3-C3 -> 2 | E3: 8 | F3: =C3/E3 -> 0.75
B4: Page layout and visual design | C4: =COUNTIFS(SuccessCriteria!B3:B49,"="&B4,SuccessCriteria!F3:F49,1) -> 15 | D4: =E4-C4 -> 2 | E4: 17 | F4: =C4/E4 -> 0.88235294
B5: Content design | C5: =COUNTIFS(SuccessCriteria!B4:B50,"="&B5,SuccessCriteria!F4:F50,1) -> 8 | D5: =E5-C5 -> 1 | E5: 9 | F5: =C5/E5 -> 0.88888889
B6: Accessibility | C6: =COUNTIFS(SuccessCriteria!B5:B51,"="&B6,SuccessCriteria!F5:F51,1) -> 4 | D6: =E6-C6 -> 3 | E6: 7 | F6: =C6/E6 -> 0.57142857
B7: Testing | C7: =COUNTIFS(SuccessCriteria!B6:B52,"="&B7,SuccessCriteria!F6:F52,1) -> 6 | D7: =E7-C7 -> 0 | E7: 6 | F7: =C7/E7 -> 1
B8: Summary | C8: =SUM(C3:C7) -> 39 | D8: =SUM(D3:D7) -> 8 | E8: =SUM(E3:E7) -> 47 | F8: =C8/E8 -> 0.82978723
F25: Az űrlapot Abonyi-Tóth Andor (ELTE IK) készítette

Sheet Ponthatárok
B1: Honlap irányelvek
C2: =Cover!D11 -> 100
B3: 0.49 | C3: -100 | D3: insufficient | H3: 56 | I3: 29 | J3: =(H3-I3)*16/56 -> 7.7142857
B4: 0.62 | C4: =ROUNDDOWN($C$2*B3+1,0) -> 50 | D4: sufficient | H4: =H3/2 -> 28
B5: 0.75 | C5: =ROUNDDOWN($C$2*B4+1,0) -> 63 | D5: average
B6: 0.88 | C6: =ROUNDDOWN($C$2*B5+1,0) -> 76 | D6: good
B7: 1 | C7: =ROUNDDOWN($C$2*B6+1,0) -> 89 | D7: excellent
D9: TRUE
D10: FALSE
